{
 "cells": [
  {
   "cell_type": "code",
   "execution_count": 1,
   "metadata": {},
   "outputs": [],
   "source": [
    "d = {\"key\": \"value\", \"key1\": \"value1\"}"
   ]
  },
  {
   "cell_type": "code",
   "execution_count": 2,
   "metadata": {},
   "outputs": [
    {
     "data": {
      "text/plain": [
       "'value'"
      ]
     },
     "execution_count": 2,
     "metadata": {},
     "output_type": "execute_result"
    }
   ],
   "source": [
    "d['key']"
   ]
  },
  {
   "cell_type": "code",
   "execution_count": 3,
   "metadata": {},
   "outputs": [
    {
     "ename": "AttributeError",
     "evalue": "'dict' object has no attribute 'key'",
     "output_type": "error",
     "traceback": [
      "\u001b[1;31m---------------------------------------------------------------------------\u001b[0m",
      "\u001b[1;31mAttributeError\u001b[0m                            Traceback (most recent call last)",
      "Cell \u001b[1;32mIn[3], line 1\u001b[0m\n\u001b[1;32m----> 1\u001b[0m \u001b[43md\u001b[49m\u001b[38;5;241;43m.\u001b[39;49m\u001b[43mkey\u001b[49m\n",
      "\u001b[1;31mAttributeError\u001b[0m: 'dict' object has no attribute 'key'"
     ]
    }
   ],
   "source": [
    "d.key"
   ]
  },
  {
   "cell_type": "code",
   "execution_count": 3,
   "metadata": {},
   "outputs": [
    {
     "name": "stdout",
     "output_type": "stream",
     "text": [
      "Collecting python-boxNote: you may need to restart the kernel to use updated packages.\n",
      "\n",
      "  Using cached python_box-7.2.0-cp38-cp38-win_amd64.whl.metadata (8.0 kB)\n",
      "Using cached python_box-7.2.0-cp38-cp38-win_amd64.whl (1.2 MB)\n",
      "Installing collected packages: python-box\n",
      "Successfully installed python-box-7.2.0\n"
     ]
    }
   ],
   "source": [
    "pip install python-box\n"
   ]
  },
  {
   "cell_type": "code",
   "execution_count": 4,
   "metadata": {},
   "outputs": [],
   "source": [
    "from box import ConfigBox"
   ]
  },
  {
   "cell_type": "code",
   "execution_count": 5,
   "metadata": {},
   "outputs": [],
   "source": [
    "d2 = ConfigBox({\"key\": \"value\", \"key1\": \"value1\"})"
   ]
  },
  {
   "cell_type": "code",
   "execution_count": 6,
   "metadata": {},
   "outputs": [
    {
     "data": {
      "text/plain": [
       "ConfigBox({'key': 'value', 'key1': 'value1'})"
      ]
     },
     "execution_count": 6,
     "metadata": {},
     "output_type": "execute_result"
    }
   ],
   "source": [
    "d2"
   ]
  },
  {
   "cell_type": "code",
   "execution_count": 7,
   "metadata": {},
   "outputs": [
    {
     "data": {
      "text/plain": [
       "'value'"
      ]
     },
     "execution_count": 7,
     "metadata": {},
     "output_type": "execute_result"
    }
   ],
   "source": [
    "d2.key"
   ]
  },
  {
   "cell_type": "markdown",
   "metadata": {},
   "source": [
    "## Use of ensure annotations"
   ]
  },
  {
   "cell_type": "code",
   "execution_count": 8,
   "metadata": {},
   "outputs": [],
   "source": [
    "def get_product(x:int, y:int) -> int:\n",
    "    return x*y"
   ]
  },
  {
   "cell_type": "code",
   "execution_count": 9,
   "metadata": {},
   "outputs": [
    {
     "data": {
      "text/plain": [
       "8"
      ]
     },
     "execution_count": 9,
     "metadata": {},
     "output_type": "execute_result"
    }
   ],
   "source": [
    "get_product(x=2, y=4)"
   ]
  },
  {
   "cell_type": "code",
   "execution_count": 10,
   "metadata": {},
   "outputs": [
    {
     "data": {
      "text/plain": [
       "'44'"
      ]
     },
     "execution_count": 10,
     "metadata": {},
     "output_type": "execute_result"
    }
   ],
   "source": [
    "get_product(x=2, y='4')"
   ]
  },
  {
   "cell_type": "code",
   "execution_count": 12,
   "metadata": {},
   "outputs": [
    {
     "name": "stdout",
     "output_type": "stream",
     "text": [
      "Collecting ensure\n",
      "  Using cached ensure-1.0.4-py3-none-any.whl.metadata (10 kB)\n",
      "Requirement already satisfied: six>=1.11.0 in c:\\users\\kumar\\anaconda3\\envs\\texts\\lib\\site-packages (from ensure) (1.16.0)\n",
      "Using cached ensure-1.0.4-py3-none-any.whl (15 kB)\n",
      "Installing collected packages: ensure\n",
      "Successfully installed ensure-1.0.4\n",
      "Note: you may need to restart the kernel to use updated packages.\n"
     ]
    }
   ],
   "source": [
    "pip install ensure"
   ]
  },
  {
   "cell_type": "code",
   "execution_count": 13,
   "metadata": {},
   "outputs": [],
   "source": [
    "from ensure import ensure_annotations"
   ]
  },
  {
   "cell_type": "code",
   "execution_count": 14,
   "metadata": {},
   "outputs": [],
   "source": [
    "@ensure_annotations\n",
    "def get_product(x:int, y:int) -> int:\n",
    "    return x*y"
   ]
  },
  {
   "cell_type": "code",
   "execution_count": 15,
   "metadata": {},
   "outputs": [
    {
     "data": {
      "text/plain": [
       "8"
      ]
     },
     "execution_count": 15,
     "metadata": {},
     "output_type": "execute_result"
    }
   ],
   "source": [
    "get_product(x=2, y=4)"
   ]
  },
  {
   "cell_type": "code",
   "execution_count": 16,
   "metadata": {},
   "outputs": [
    {
     "name": "stdout",
     "output_type": "stream",
     "text": [
      "Unexpected exception formatting exception. Falling back to standard exception\n"
     ]
    },
    {
     "name": "stderr",
     "output_type": "stream",
     "text": [
      "Traceback (most recent call last):\n",
      "  File \"c:\\Users\\Kumar\\anaconda3\\envs\\textS\\lib\\site-packages\\IPython\\core\\interactiveshell.py\", line 3508, in run_code\n",
      "    exec(code_obj, self.user_global_ns, self.user_ns)\n",
      "  File \"C:\\Users\\Kumar\\AppData\\Local\\Temp\\ipykernel_4896\\1101396739.py\", line 1, in <module>\n",
      "    get_product(x=2, y='4')\n",
      "  File \"c:\\Users\\Kumar\\anaconda3\\envs\\textS\\lib\\site-packages\\ensure\\main.py\", line 870, in __call__\n",
      "    raise EnsureError(msg.format(arg=arg, f=self.f, t=templ, valt=type(value)))\n",
      "ensure.main.EnsureError: Argument y of type <class 'str'> to <function get_product at 0x000001965D8FBE50> does not match annotation type <class 'int'>\n",
      "\n",
      "During handling of the above exception, another exception occurred:\n",
      "\n",
      "Traceback (most recent call last):\n",
      "  File \"c:\\Users\\Kumar\\anaconda3\\envs\\textS\\lib\\site-packages\\IPython\\core\\interactiveshell.py\", line 2105, in showtraceback\n",
      "    stb = self.InteractiveTB.structured_traceback(\n",
      "  File \"c:\\Users\\Kumar\\anaconda3\\envs\\textS\\lib\\site-packages\\IPython\\core\\ultratb.py\", line 1396, in structured_traceback\n",
      "    return FormattedTB.structured_traceback(\n",
      "  File \"c:\\Users\\Kumar\\anaconda3\\envs\\textS\\lib\\site-packages\\IPython\\core\\ultratb.py\", line 1287, in structured_traceback\n",
      "    return VerboseTB.structured_traceback(\n",
      "  File \"c:\\Users\\Kumar\\anaconda3\\envs\\textS\\lib\\site-packages\\IPython\\core\\ultratb.py\", line 1140, in structured_traceback\n",
      "    formatted_exception = self.format_exception_as_a_whole(etype, evalue, etb, number_of_lines_of_context,\n",
      "  File \"c:\\Users\\Kumar\\anaconda3\\envs\\textS\\lib\\site-packages\\IPython\\core\\ultratb.py\", line 1055, in format_exception_as_a_whole\n",
      "    frames.append(self.format_record(record))\n",
      "  File \"c:\\Users\\Kumar\\anaconda3\\envs\\textS\\lib\\site-packages\\IPython\\core\\ultratb.py\", line 955, in format_record\n",
      "    frame_info.lines, Colors, self.has_colors, lvals\n",
      "  File \"c:\\Users\\Kumar\\anaconda3\\envs\\textS\\lib\\site-packages\\IPython\\core\\ultratb.py\", line 778, in lines\n",
      "    return self._sd.lines\n",
      "  File \"c:\\Users\\Kumar\\anaconda3\\envs\\textS\\lib\\site-packages\\stack_data\\utils.py\", line 144, in cached_property_wrapper\n",
      "    value = obj.__dict__[self.func.__name__] = self.func(obj)\n",
      "  File \"c:\\Users\\Kumar\\anaconda3\\envs\\textS\\lib\\site-packages\\stack_data\\core.py\", line 734, in lines\n",
      "    pieces = self.included_pieces\n",
      "  File \"c:\\Users\\Kumar\\anaconda3\\envs\\textS\\lib\\site-packages\\stack_data\\utils.py\", line 144, in cached_property_wrapper\n",
      "    value = obj.__dict__[self.func.__name__] = self.func(obj)\n",
      "  File \"c:\\Users\\Kumar\\anaconda3\\envs\\textS\\lib\\site-packages\\stack_data\\core.py\", line 677, in included_pieces\n",
      "    scope_pieces = self.scope_pieces\n",
      "  File \"c:\\Users\\Kumar\\anaconda3\\envs\\textS\\lib\\site-packages\\stack_data\\utils.py\", line 144, in cached_property_wrapper\n",
      "    value = obj.__dict__[self.func.__name__] = self.func(obj)\n",
      "  File \"c:\\Users\\Kumar\\anaconda3\\envs\\textS\\lib\\site-packages\\stack_data\\core.py\", line 614, in scope_pieces\n",
      "    scope_start, scope_end = self.source.line_range(self.scope)\n",
      "  File \"c:\\Users\\Kumar\\anaconda3\\envs\\textS\\lib\\site-packages\\stack_data\\core.py\", line 178, in line_range\n",
      "    return line_range(self.asttext(), node)\n",
      "AttributeError: 'Source' object has no attribute 'asttext'\n"
     ]
    }
   ],
   "source": [
    "get_product(x=2, y='4')"
   ]
  },
  {
   "cell_type": "code",
   "execution_count": null,
   "metadata": {},
   "outputs": [],
   "source": []
  }
 ],
 "metadata": {
  "kernelspec": {
   "display_name": "textS",
   "language": "python",
   "name": "python3"
  },
  "language_info": {
   "codemirror_mode": {
    "name": "ipython",
    "version": 3
   },
   "file_extension": ".py",
   "mimetype": "text/x-python",
   "name": "python",
   "nbconvert_exporter": "python",
   "pygments_lexer": "ipython3",
   "version": "3.8.20"
  }
 },
 "nbformat": 4,
 "nbformat_minor": 2
}
